Workbook

Sheet Q1
A1: Date | B1: Product | C1: Region | D1: SalesRep | E1: Customer | F1: Units | G1: sales | H1: Discount
A2: 40553 | B2: Carlota | C2: East | D2: Pham | E2: AA | F2: 63 | G2: 1449 | H2: 693
A3: 40544 | B3: Quad | C3: East | D3: Sioux | E3: AA | F3: 16 | G3: 432 | H3: 232 | L3: Class II Questions 1) Product and region wise maximum sales. 2) Region wise percentage and average discount. 3) Copy the data whose sales are greater than 1000 and discount less than 500. 4) Copy the data whose region is East. 5) Split the product column by starting 3 letters. 6) Highlight the units greater than 20 and less than 50. 7) Create data for January date. 8)Replace AA with RAM in Customer column. 9) Create charts for the following. a) Average Units by Customer and by SalesRip. b) Percentage of Discount by Region. c) Minimum and maximum Sales by Product and Customer. 10) Calculate the total for for Sales and Units
A4: 40561 | B4: Sunshine | C4: East | D4: Franks | E4: AA | F4: 24 | G4: 456 | H4: 192
A5: 40606 | B5: Sunshine | C5: East | D5: Franks | E5: AA | F5: 24 | G5: 456 | H5: 192
A6: 40572 | B6: Bellen | C6: East | D6: Chin | E6: AST | F6: 50 | G6: 1100 | H6: 500
A7: 40565 | B7: Bellen | C7: West | D7: Pham | E7: AST | F7: 53 | G7: 1166 | H7: 530
A8: 40610 | B8: Bellen | C8: West | D8: Pham | E8: AST | F8: 53 | G8: 1166 | H8: 530
A9: 40545 | B9: Quad | C9: West | D9: Pham | E9: AST | F9: 30 | G9: 810 | H9: 435
A10: 40558 | B10: Sunset | C10: East | D10: Gault | E10: AST | F10: 63 | G10: 1323 | H10: 583
A11: 40561 | B11: Sunshine | C11: West | D11: Sioux | E11: AST | F11: 8 | G11: 152 | H11: 64
A12: 40591 | B12: Sunshine | C12: West | D12: Sioux | E12: AST | F12: 8 | G12: 152 | H12: 64
A13: 40567 | B13: Carlota | C13: MidWest | D13: Franks | E13: BBT | F13: 13 | G13: 299 | H13: 143
A14: 40612 | B14: Carlota | C14: MidWest | D14: Franks | E14: BBT | F14: 13 | G14: 299 | H14: 143
A15: 40554 | B15: Quad | C15: East | D15: Smith | E15: BBT | F15: 49 | G15: 1323 | H15: 711
... A136: 40571 | B136: Sunset | C136: East | D136: Smith | E136: ZAT | F136: 36 | G136: 756 | H136: 333
F137: =SUM(F2:F136) -> 4587 | G137: =SUM(G1:G136) -> 107605

Sheet 1,2,3,4 ans
A1: Date | B1: Product | C1: Region | D1: SalesRep | E1: Customer | F1: Units | G1: sales | H1: Discount
A2: 40553 | B2: Carlota | C2: East | D2: Pham | E2: AA | F2: 63 | G2: 1449 | H2: 693 | K2: 1) Product and region wise maximum sales. | W2: 3) Copy the data whose sales are greater than 1000 and discount less than 500.
A3: 40544 | B3: Quad | C3: East | D3: Sioux | E3: AA | F3: 16 | G3: 432 | H3: 232 | K3: Max of sales | L3: Region
A4: 40561 | B4: Sunshine | C4: East | D4: Franks | E4: AA | F4: 24 | G4: 456 | H4: 192 | K4: Product | L4: East | M4: MidWest | N4: South | O4: West | P4: Grand Total | S4: Date | T4: Product | U4: Region | V4: SalesRep | W4: Customer | X4: Units | Y4: sales | Z4: Discount
A5: 40606 | B5: Sunshine | C5: East | D5: Franks | E5: AA | F5: 24 | G5: 456 | H5: 192 | K5: Bellen | L5: 1298 | M5: 1254 | N5: 770 | O5: 5000 | P5: 5000 | S5: 40560 | T5: Sunshine | U5: MidWest | V5: Franks | W5: HHH | X5: 59 | Y5: 1121 | Z5: 472
A6: 40572 | B6: Bellen | C6: East | D6: Chin | E6: AST | F6: 50 | G6: 1100 | H6: 500 | K6: Carlota | L6: 1449 | M6: 460 | N6: 1219 | O6: 1380 | P6: 1449 | S6: 40561 | T6: Sunshine | U6: MidWest | V6: Chin | W6: PCC | X6: 62 | Y6: 1178 | Z6: 496
A7: 40565 | B7: Bellen | C7: West | D7: Pham | E7: AST | F7: 53 | G7: 1166 | H7: 530 | K7: Quad | L7: 1674 | M7: 1647 | N7: 1512 | O7: 1755 | P7: 1755 | S7: 40606 | T7: Sunshine | U7: MidWest | V7: Chin | W7: PCC | X7: 62 | Y7: 1178 | Z7: 496
A8: 40610 | B8: Bellen | C8: West | D8: Pham | E8: AST | F8: 53 | G8: 1166 | H8: 530 | K8: Sunset | L8: 1323 | M8: 609 | N8: 1197 | O8: 1302 | P8: 1323 | S8: 40549 | T8: Sunshine | U8: East | V8: Franks | W8: PSA | X8: 54 | Y8: 1026 | Z8: 432
A9: 40545 | B9: Quad | C9: West | D9: Pham | E9: AST | F9: 30 | G9: 810 | H9: 435 | K9: Sunshine | L9: 1026 | M9: 1216 | N9: 969 | O9: 1102 | P9: 1216 | S9: 40550 | T9: Sunset | U9: West | V9: Pham | W9: WT | X9: 53 | Y9: 1113 | Z9: 490
A10: 40558 | B10: Sunset | C10: East | D10: Gault | E10: AST | F10: 63 | G10: 1323 | H10: 583 | K10: Grand Total | L10: 1674 | M10: 1647 | N10: 1512 | O10: 5000 | P10: 5000 | S10: 40563 | T10: Sunshine | U10: West | V10: Sioux | W10: YTR | X10: 58 | Y10: 1102 | Z10: 464
A11: 40561 | B11: Sunshine | C11: West | D11: Sioux | E11: AST | F11: 8 | G11: 152 | H11: 64
A12: 40591 | B12: Sunshine | C12: West | D12: Sioux | E12: AST | F12: 8 | G12: 152 | H12: 64 | S12: 4) Copy the data whose region is East.
A13: 40567 | B13: Carlota | C13: MidWest | D13: Franks | E13: BBT | F13: 13 | G13: 299 | H13: 143 | K13: 2) Region wise percentage and average discount.
A14: 40612 | B14: Carlota | C14: MidWest | D14: Franks | E14: BBT | F14: 13 | G14: 299 | H14: 143 | S14: Date | T14: Product | U14: Region | V14: SalesRep | W14: Customer | X14: Units | Y14: sales | Z14: Discount
A15: 40554 | B15: Quad | C15: East | D15: Smith | E15: BBT | F15: 49 | G15: 1323 | H15: 711 | S15: 40553 | T15: Carlota | U15: East | V15: Pham | W15: AA | X15: 63 | Y15: 1449 | Z15: 693
A16: 40547 | B16: Sunset | C16: MidWest | D16: Sioux | E16: BBT | F16: 29 | G16: 609 | H16: 268 | K16: Region | L16: Average of Discount | M16: Sum of Discount | S16: 40544 | T16: Quad | U16: East | V16: Sioux | W16: AA | X16: 16 | Y16: 432 | Z16: 232
A17: 40561 | B17: Bellen | C17: East | D17: Franks | E17: DFGH | F17: 20 | G17: 440 | H17: 200 | K17: East | L17: 408.4359 | M17: 0.32212336 | S17: 40561 | T17: Sunshine | U17: East | V17: Franks | W17: AA | X17: 24 | Y17: 456 | Z17: 192
A18: 40566 | B18: Bellen | C18: East | D18: Gault | E18: DFGH | F18: 9 | G18: 198 | H18: 90 | K18: MidWest | L18: 293.41935 | M18: 0.18394338 | S18: 40606 | T18: Sunshine | U18: East | V18: Franks | W18: AA | X18: 24 | Y18: 456 | Z18: 192
A19: 40611 | B19: Bellen | C19: East | D19: Gault | E19: DFGH | F19: 9 | G19: 198 | H19: 90 | K19: South | L19: 356.17647 | M19: 0.24489383 | S19: 40572 | T19: Bellen | U19: East | V19: Chin | W19: AST | X19: 50 | Y19: 1100 | Z19: 500
A20: 40569 | B20: Sunset | C20: South | D20: Sioux | E20: DFGH | F20: 44 | G20: 924 | H20: 407 | K20: West | L20: 397.25806 | M20: 0.24903943 | S20: 40558 | T20: Sunset | U20: East | V20: Gault | W20: AST | X20: 63 | Y20: 1323 | Z20: 583
A21: 40561 | B21: Bellen | C21: East | D21: Pham | E21: DFR | F21: 59 | G21: 1298 | H21: 590 | K21: (blank) | M21: 0 | S21: 40554 | T21: Quad | U21: East | V21: Smith | W21: BBT | X21: 49 | Y21: 1323 | Z21: 711
A22: 40553 | B22: Quad | C22: East | D22: Smith | E22: DFR | F22: 17 | G22: 459 | H22: 247 | K22: Grand Total | L22: 366.2963 | M22: 1 | S22: 40561 | T22: Bellen | U22: East | V22: Franks | W22: DFGH | X22: 20 | Y22: 440 | Z22: 200
A23: 40564 | B23: Sunshine | C23: MidWest | D23: Pham | E23: DFR | F23: 23 | G23: 437 | H23: 184 | S23: 40566 | T23: Bellen | U23: East | V23: Gault | W23: DFGH | X23: 9 | Y23: 198 | Z23: 90
A24: 40573 | B24: Sunshine | C24: West | D24: Gault | E24: DFR | F24: 49 | G24: 931 | H24: 392 | S24: 40611 | T24: Bellen | U24: East | V24: Gault | W24: DFGH | X24: 9 | Y24: 198 | Z24: 90
A25: 40552 | B25: Bellen | C25: East | D25: Pham | E25: EPP | F25: 40 | G25: 880 | H25: 400 | S25: 40561 | T25: Bellen | U25: East | V25: Pham | W25: DFR | X25: 59 | Y25: 1298 | Z25: 590
A26: 40597 | B26: Bellen | C26: East | D26: Pham | E26: EPP | F26: 40 | G26: 880 | H26: 400 | S26: 40553 | T26: Quad | U26: East | V26: Smith | W26: DFR | X26: 17 | Y26: 459 | Z26: 247
A27: 40560 | B27: Quad | C27: MidWest | D27: Chin | E27: EPP | F27: 61 | G27: 1647 | H27: 885 | S27: 40552 | T27: Bellen | U27: East | V27: Pham | W27: EPP | X27: 40 | Y27: 880 | Z27: 400
A28: 40563 | B28: Carlota | C28: East | D28: Chin | E28: ET | F28: 59 | G28: 1357 | H28: 649 | S28: 40597 | T28: Bellen | U28: East | V28: Pham | W28: EPP | X28: 40 | Y28: 880 | Z28: 400
A29: 40593 | B29: Carlota | C29: East | D29: Chin | E29: ET | F29: 59 | G29: 1357 | H29: 649 | S29: 40563 | T29: Carlota | U29: East | V29: Chin | W29: ET | X29: 59 | Y29: 1357 | Z29: 649
A30: 40548 | B30: Sunshine | C30: West | D30: Franks | E30: ET | F30: 12 | G30: 228 | H30: 96 | S30: 40593 | T30: Carlota | U30: East | V30: Chin | W30: ET | X30: 59 | Y30: 1357 | Z30: 649
A31: 40593 | B31: Sunshine | C31: West | D31: Franks | E31: ET | F31: 12 | G31: 228 | H31: 96 | S31: 40564 | T31: Quad | U31: East | V31: Chin | W31: FM | X31: 58 | Y31: 1566 | Z31: 841
A32: 40553 | B32: Bellen | C32: MidWest | D32: Gault | E32: FM | F32: 7 | G32: 154 | H32: 70 | S32: 40546 | T32: Sunshine | U32: East | V32: Pham | W32: FM | X32: 38 | Y32: 722 | Z32: 304
A33: 40546 | B33: Carlota | C33: MidWest | D33: Chin | E33: FM | F33: 20 | G33: 460 | H33: 220 | S33: 40560 | T33: Quad | U33: East | V33: Franks | W33: HII | X33: 62 | Y33: 1674 | Z33: 899
A34: 40591 | B34: Carlota | C34: MidWest | D34: Chin | E34: FM | F34: 20 | G34: 460 | H34: 220 | S34: 40590 | T34: Quad | U34: East | V34: Franks | W34: HII | X34: 62 | Y34: 1674 | Z34: 899
... A53: 40554 | B53: Quad | C53: East | D53: Franks | E53: ITW | F53: 14 | G53: 378 | H53: 203 | S53: 40571 | T53: Sunset | U53: East | V53: Smith | W53: ZAT | X53: 36 | Y53: 756 | Z53: 333
A54: 40599 | B54: Quad | C54: East | D54: Franks | E54: ITW | F54: 14 | G54: 378 | H54: 203
A55: 40564 | B55: Quad | C55: West | D55: Gault | E55: ITW | F55: 56 | G55: 1512 | H55: 812
A56: 40555 | B56: Sunset | C56: MidWest | D56: Gault | E56: ITW | F56: 19 | G56: 399 | H56: 176
A57: 40557 | B57: Carlota | C57: East | D57: Franks | E57: JAQ | F57: 34 | G57: 782 | H57: 374
A58: 40568 | B58: Sunshine | C58: MidWest | D58: Franks | E58: JAQ | F58: 21 | G58: 399 | H58: 168
...

Sheet 5,6,7,8,9
A1: Split the product column by starting 3 letters. | K1: 6) Highlight the units greater than 20 and less than 50. | T1: 7) Create data for January date. | AD1: 8)Replace AA with RAM in Customer column. | AM1: 9) Create charts for the following. | BU1: b,Percentage of Discount by Region. | CD1: c) Minimum and maximum Sales by Product and Customer.
A2: Date | B2: Product | C2: Region | D2: SalesRep | E2: Customer | F2: Units | G2: sales | H2: Discount | I2: Product 3 letter | K2: Date | L2: Product | M2: Region | N2: SalesRep | O2: Customer | P2: Units | Q2: sales | R2: Discount | T2: Date | U2: Product | V2: Region | W2: SalesRep | X2: Customer | Y2: Units | Z2: sales | AA2: Discount | AD2: Date | AE2: Product | AF2: Region | AG2: SalesRep | AH2: Customer | AI2: Units | AJ2: sales | AK2: Discount | AM2: a.Average Units by Customer and SalesRep.
A3: 40553 | B3: Carlota | C3: East | D3: Pham | E3: AA | F3: 63 | G3: 1449 | H3: 693 | I3: =LEFT(B3,3) -> Car | K3: 40553 | L3: Carlota | M3: East | N3: Pham | O3: AA | P3: 63 | Q3: 1449 | R3: 693 | T3: 40553 | U3: Carlota | V3: East | W3: Pham | X3: AA | Y3: 63 | Z3: 1449 | AA3: 693 | AD3: 40553 | AE3: Carlota | AF3: East | AG3: Pham | AH3: RAM | AI3: 63 | AJ3: 1449 | AK3: 693 | AM3: Customer | AN3: SalesRep | AO3: Average of Units | BU3: Region | BV3: percentage of Discount | CD3: Customer | CE3: Product | CF3: Min of sales | CG3: Max of sales2
A4: 40544 | B4: Quad | C4: East | D4: Sioux | E4: AA | F4: 16 | G4: 432 | H4: 232 | I4: =LEFT(B4,3) -> Qua | K4: 40544 | L4: Quad | M4: East | N4: Sioux | O4: AA | P4: 16 | Q4: 432 | R4: 232 | T4: 40544 | U4: Quad | V4: East | W4: Sioux | X4: AA | Y4: 16 | Z4: 432 | AA4: 232 | AD4: 40544 | AE4: Quad | AF4: East | AG4: Sioux | AH4: RAM | AI4: 16 | AJ4: 432 | AK4: 232 | AM4: AA | AN4: Franks | AO4: 24 | BU4: East | BV4: 0.32212336 | CD4: AA | CE4: Carlota | CF4: 1449 | CG4: 1449
A5: 40561 | B5: Sunshine | C5: East | D5: Franks | E5: AA | F5: 24 | G5: 456 | H5: 192 | I5: =LEFT(B5,3) -> Sun | K5: 40561 | L5: Sunshine | M5: East | N5: Franks | O5: AA | P5: 24 | Q5: 456 | R5: 192 | T5: 40561 | U5: Sunshine | V5: East | W5: Franks | X5: AA | Y5: 24 | Z5: 456 | AA5: 192 | AD5: 40561 | AE5: Sunshine | AF5: East | AG5: Franks | AH5: RAM | AI5: 24 | AJ5: 456 | AK5: 192 | AN5: Pham | AO5: 63 | BU5: MidWest | BV5: 0.18394338 | CE5: Quad | CF5: 432 | CG5: 432
A6: 40606 | B6: Sunshine | C6: East | D6: Franks | E6: AA | F6: 24 | G6: 456 | H6: 192 | I6: =LEFT(B6,3) -> Sun | K6: 40606 | L6: Sunshine | M6: East | N6: Franks | O6: AA | P6: 24 | Q6: 456 | R6: 192 | T6: 40606 | U6: Sunshine | V6: East | W6: Franks | X6: AA | Y6: 24 | Z6: 456 | AA6: 192 | AD6: 40606 | AE6: Sunshine | AF6: East | AG6: Franks | AH6: AA | AI6: 24 | AJ6: 456 | AK6: 192 | AN6: Sioux | AO6: 16 | BU6: South | BV6: 0.24489383 | CE6: Sunshine | CF6: 456 | CG6: 456
A7: 40572 | B7: Bellen | C7: East | D7: Chin | E7: AST | F7: 50 | G7: 1100 | H7: 500 | I7: =LEFT(B7,3) -> Bel | K7: 40572 | L7: Bellen | M7: East | N7: Chin | O7: AST | P7: 50 | Q7: 1100 | R7: 500 | T7: 40572 | U7: Bellen | V7: East | W7: Chin | X7: AST | Y7: 50 | Z7: 1100 | AA7: 500 | AD7: 40572 | AE7: Bellen | AF7: East | AG7: Chin | AH7: AST | AI7: 50 | AJ7: 1100 | AK7: 500 | AM7: AA Total | AO7: 31.75 | BU7: West | BV7: 0.24903943 | CD7: AA Total | CF7: 432 | CG7: 1449
A8: 40565 | B8: Bellen | C8: West | D8: Pham | E8: AST | F8: 53 | G8: 1166 | H8: 530 | I8: =LEFT(B8,3) -> Bel | K8: 40565 | L8: Bellen | M8: West | N8: Pham | O8: AST | P8: 53 | Q8: 1166 | R8: 530 | T8: 40565 | U8: Bellen | V8: West | W8: Pham | X8: AST | Y8: 53 | Z8: 1166 | AA8: 530 | AD8: 40565 | AE8: Bellen | AF8: West | AG8: Pham | AH8: AST | AI8: 53 | AJ8: 1166 | AK8: 530 | AM8: AST | AN8: Chin | AO8: 50 | BU8: Grand Total | BV8: 1 | CD8: AST | CE8: Bellen | CF8: 1100 | CG8: 1166
A9: 40610 | B9: Bellen | C9: West | D9: Pham | E9: AST | F9: 53 | G9: 1166 | H9: 530 | I9: =LEFT(B9,3) -> Bel | K9: 40610 | L9: Bellen | M9: West | N9: Pham | O9: AST | P9: 53 | Q9: 1166 | R9: 530 | T9: 40610 | U9: Bellen | V9: West | W9: Pham | X9: AST | Y9: 53 | Z9: 1166 | AA9: 530 | AD9: 40610 | AE9: Bellen | AF9: West | AG9: Pham | AH9: AST | AI9: 53 | AJ9: 1166 | AK9: 530 | AN9: Gault | AO9: 63 | CE9: Quad | CF9: 810 | CG9: 810
A10: 40545 | B10: Quad | C10: West | D10: Pham | E10: AST | F10: 30 | G10: 810 | H10: 435 | I10: =LEFT(B10,3) -> Qua | K10: 40545 | L10: Quad | M10: West | N10: Pham | O10: AST | P10: 30 | Q10: 810 | R10: 435 | T10: 40545 | U10: Quad | V10: West | W10: Pham | X10: AST | Y10: 30 | Z10: 810 | AA10: 435 | AD10: 40545 | AE10: Quad | AF10: West | AG10: Pham | AH10: AST | AI10: 30 | AJ10: 810 | AK10: 435 | AN10: Pham | AO10: 45.333333 | CE10: Sunset | CF10: 1323 | CG10: 1323
A11: 40558 | B11: Sunset | C11: East | D11: Gault | E11: AST | F11: 63 | G11: 1323 | H11: 583 | I11: =LEFT(B11,3) -> Sun | K11: 40558 | L11: Sunset | M11: East | N11: Gault | O11: AST | P11: 63 | Q11: 1323 | R11: 583 | T11: 40558 | U11: Sunset | V11: East | W11: Gault | X11: AST | Y11: 63 | Z11: 1323 | AA11: 583 | AD11: 40558 | AE11: Sunset | AF11: East | AG11: Gault | AH11: AST | AI11: 63 | AJ11: 1323 | AK11: 583 | AN11: Sioux | AO11: 8 | CE11: Sunshine | CF11: 152 | CG11: 152
A12: 40561 | B12: Sunshine | C12: West | D12: Sioux | E12: AST | F12: 8 | G12: 152 | H12: 64 | I12: =LEFT(B12,3) -> Sun | K12: 40561 | L12: Sunshine | M12: West | N12: Sioux | O12: AST | P12: 8 | Q12: 152 | R12: 64 | T12: 40561 | U12: Sunshine | V12: West | W12: Sioux | X12: AST | Y12: 8 | Z12: 152 | AA12: 64 | AD12: 40561 | AE12: Sunshine | AF12: West | AG12: Sioux | AH12: AST | AI12: 8 | AJ12: 152 | AK12: 64 | AM12: AST Total | AO12: 37.857143 | CD12: AST Total | CF12: 152 | CG12: 1323
A13: 40591 | B13: Sunshine | C13: West | D13: Sioux | E13: AST | F13: 8 | G13: 152 | H13: 64 | I13: =LEFT(B13,3) -> Sun | K13: 40591 | L13: Sunshine | M13: West | N13: Sioux | O13: AST | P13: 8 | Q13: 152 | R13: 64 | T13: 40591 | U13: Sunshine | V13: West | W13: Sioux | X13: AST | Y13: 8 | Z13: 152 | AA13: 64 | AD13: 40591 | AE13: Sunshine | AF13: West | AG13: Sioux | AH13: AST | AI13: 8 | AJ13: 152 | AK13: 64 | AM13: BBT | AN13: Franks | AO13: 13 | CD13: BBT | CE13: Carlota | CF13: 299 | CG13: 299
A14: 40567 | B14: Carlota | C14: MidWest | D14: Franks | E14: BBT | F14: 13 | G14: 299 | H14: 143 | I14: =LEFT(B14,3) -> Car | K14: 40567 | L14: Carlota | M14: MidWest | N14: Franks | O14: BBT | P14: 13 | Q14: 299 | R14: 143 | T14: 40567 | U14: Carlota | V14: MidWest | W14: Franks | X14: BBT | Y14: 13 | Z14: 299 | AA14: 143 | AD14: 40567 | AE14: Carlota | AF14: MidWest | AG14: Franks | AH14: BBT | AI14: 13 | AJ14: 299 | AK14: 143 | AN14: Sioux | AO14: 29 | CE14: Quad | CF14: 1323 | CG14: 1323
A15: 40612 | B15: Carlota | C15: MidWest | D15: Franks | E15: BBT | F15: 13 | G15: 299 | H15: 143 | I15: =LEFT(B15,3) -> Car | K15: 40612 | L15: Carlota | M15: MidWest | N15: Franks | O15: BBT | P15: 13 | Q15: 299 | R15: 143 | T15: 40612 | U15: Carlota | V15: MidWest | W15: Franks | X15: BBT | Y15: 13 | Z15: 299 | AA15: 143 | AD15: 40612 | AE15: Carlota | AF15: MidWest | AG15: Franks | AH15: BBT | AI15: 13 | AJ15: 299 | AK15: 143 | AN15: Smith | AO15: 49 | CE15: Sunset | CF15: 609 | CG15: 609
A16: 40554 | B16: Quad | C16: East | D16: Smith | E16: BBT | F16: 49 | G16: 1323 | H16: 711 | I16: =LEFT(B16,3) -> Qua | K16: 40554 | L16: Quad | M16: East | N16: Smith | O16: BBT | P16: 49 | Q16: 1323 | R16: 711 | T16: 40554 | U16: Quad | V16: East | W16: Smith | X16: BBT | Y16: 49 | Z16: 1323 | AA16: 711 | AD16: 40554 | AE16: Quad | AF16: East | AG16: Smith | AH16: BBT | AI16: 49 | AJ16: 1323 | AK16: 711 | AM16: BBT Total | AO16: 26 | CD16: BBT Total | CF16: 299 | CG16: 1323
A17: 40547 | B17: Sunset | C17: MidWest | D17: Sioux | E17: BBT | F17: 29 | G17: 609 | H17: 268 | I17: =LEFT(B17,3) -> Sun | K17: 40547 | L17: Sunset | M17: MidWest | N17: Sioux | O17: BBT | P17: 29 | Q17: 609 | R17: 268 | T17: 40547 | U17: Sunset | V17: MidWest | W17: Sioux | X17: BBT | Y17: 29 | Z17: 609 | AA17: 268 | AD17: 40547 | AE17: Sunset | AF17: MidWest | AG17: Sioux | AH17: BBT | AI17: 29 | AJ17: 609 | AK17: 268 | AM17: DFGH | AN17: Franks | AO17: 20 | CD17: DFGH | CE17: Bellen | CF17: 198 | CG17: 440
A18: 40561 | B18: Bellen | C18: East | D18: Franks | E18: DFGH | F18: 20 | G18: 440 | H18: 200 | I18: =LEFT(B18,3) -> Bel | K18: 40561 | L18: Bellen | M18: East | N18: Franks | O18: DFGH | P18: 20 | Q18: 440 | R18: 200 | T18: 40561 | U18: Bellen | V18: East | W18: Franks | X18: DFGH | Y18: 20 | Z18: 440 | AA18: 200 | AD18: 40561 | AE18: Bellen | AF18: East | AG18: Franks | AH18: DFGH | AI18: 20 | AJ18: 440 | AK18: 200 | AN18: Gault | AO18: 9 | CE18: Sunset | CF18: 924 | CG18: 924
A19: 40566 | B19: Bellen | C19: East | D19: Gault | E19: DFGH | F19: 9 | G19: 198 | H19: 90 | I19: =LEFT(B19,3) -> Bel | K19: 40566 | L19: Bellen | M19: East | N19: Gault | O19: DFGH | P19: 9 | Q19: 198 | R19: 90 | T19: 40566 | U19: Bellen | V19: East | W19: Gault | X19: DFGH | Y19: 9 | Z19: 198 | AA19: 90 | AD19: 40566 | AE19: Bellen | AF19: East | AG19: Gault | AH19: DFGH | AI19: 9 | AJ19: 198 | AK19: 90 | AN19: Sioux | AO19: 44 | CD19: DFGH Total | CF19: 198 | CG19: 924
A20: 40611 | B20: Bellen | C20: East | D20: Gault | E20: DFGH | F20: 9 | G20: 198 | H20: 90 | I20: =LEFT(B20,3) -> Bel | K20: 40611 | L20: Bellen | M20: East | N20: Gault | O20: DFGH | P20: 9 | Q20: 198 | R20: 90 | T20: 40611 | U20: Bellen | V20: East | W20: Gault | X20: DFGH | Y20: 9 | Z20: 198 | AA20: 90 | AD20: 40611 | AE20: Bellen | AF20: East | AG20: Gault | AH20: DFGH | AI20: 9 | AJ20: 198 | AK20: 90 | AM20: DFGH Total | AO20: 20.5 | CD20: DFR | CE20: Bellen | CF20: 1298 | CG20: 1298
A21: 40569 | B21: Sunset | C21: South | D21: Sioux | E21: DFGH | F21: 44 | G21: 924 | H21: 407 | I21: =LEFT(B21,3) -> Sun | K21: 40569 | L21: Sunset | M21: South | N21: Sioux | O21: DFGH | P21: 44 | Q21: 924 | R21: 407 | T21: 40569 | U21: Sunset | V21: South | W21: Sioux | X21: DFGH | Y21: 44 | Z21: 924 | AA21: 407 | AD21: 40569 | AE21: Sunset | AF21: South | AG21: Sioux | AH21: DFGH | AI21: 44 | AJ21: 924 | AK21: 407 | AM21: DFR | AN21: Gault | AO21: 49 | CE21: Quad | CF21: 459 | CG21: 459
A22: 40561 | B22: Bellen | C22: East | D22: Pham | E22: DFR | F22: 59 | G22: 1298 | H22: 590 | I22: =LEFT(B22,3) -> Bel | K22: 40561 | L22: Bellen | M22: East | N22: Pham | O22: DFR | P22: 59 | Q22: 1298 | R22: 590 | T22: 40561 | U22: Bellen | V22: East | W22: Pham | X22: DFR | Y22: 59 | Z22: 1298 | AA22: 590 | AD22: 40561 | AE22: Bellen | AF22: East | AG22: Pham | AH22: DFR | AI22: 59 | AJ22: 1298 | AK22: 590 | AN22: Pham | AO22: 41 | CE22: Sunshine | CF22: 437 | CG22: 931
A23: 40553 | B23: Quad | C23: East | D23: Smith | E23: DFR | F23: 17 | G23: 459 | H23: 247 | I23: =LEFT(B23,3) -> Qua | K23: 40553 | L23: Quad | M23: East | N23: Smith | O23: DFR | P23: 17 | Q23: 459 | R23: 247 | T23: 40553 | U23: Quad | V23: East | W23: Smith | X23: DFR | Y23: 17 | Z23: 459 | AA23: 247 | AD23: 40553 | AE23: Quad | AF23: East | AG23: Smith | AH23: DFR | AI23: 17 | AJ23: 459 | AK23: 247 | AN23: Smith | AO23: 17 | CD23: DFR Total | CF23: 437 | CG23: 1298
A24: 40564 | B24: Sunshine | C24: MidWest | D24: Pham | E24: DFR | F24: 23 | G24: 437 | H24: 184 | I24: =LEFT(B24,3) -> Sun | K24: 40564 | L24: Sunshine | M24: MidWest | N24: Pham | O24: DFR | P24: 23 | Q24: 437 | R24: 184 | T24: 40564 | U24: Sunshine | V24: MidWest | W24: Pham | X24: DFR | Y24: 23 | Z24: 437 | AA24: 184 | AD24: 40564 | AE24: Sunshine | AF24: MidWest | AG24: Pham | AH24: DFR | AI24: 23 | AJ24: 437 | AK24: 184 | AM24: DFR Total | AO24: 37 | CD24: EPP | CE24: Bellen | CF24: 880 | CG24: 880
A25: 40573 | B25: Sunshine | C25: West | D25: Gault | E25: DFR | F25: 49 | G25: 931 | H25: 392 | I25: =LEFT(B25,3) -> Sun | K25: 40573 | L25: Sunshine | M25: West | N25: Gault | O25: DFR | P25: 49 | Q25: 931 | R25: 392 | T25: 40573 | U25: Sunshine | V25: West | W25: Gault | X25: DFR | Y25: 49 | Z25: 931 | AA25: 392 | AD25: 40573 | AE25: Sunshine | AF25: West | AG25: Gault | AH25: DFR | AI25: 49 | AJ25: 931 | AK25: 392 | AM25: EPP | AN25: Chin | AO25: 61 | CE25: Quad | CF25: 1647 | CG25: 1647
A26: 40552 | B26: Bellen | C26: East | D26: Pham | E26: EPP | F26: 40 | G26: 880 | H26: 400 | I26: =LEFT(B26,3) -> Bel | K26: 40552 | L26: Bellen | M26: East | N26: Pham | O26: EPP | P26: 40 | Q26: 880 | R26: 400 | T26: 40552 | U26: Bellen | V26: East | W26: Pham | X26: EPP | Y26: 40 | Z26: 880 | AA26: 400 | AD26: 40552 | AE26: Bellen | AF26: East | AG26: Pham | AH26: EPP | AI26: 40 | AJ26: 880 | AK26: 400 | AN26: Pham | AO26: 40 | CD26: EPP Total | CF26: 880 | CG26: 1647
A27: 40597 | B27: Bellen | C27: East | D27: Pham | E27: EPP | F27: 40 | G27: 880 | H27: 400 | I27: =LEFT(B27,3) -> Bel | K27: 40597 | L27: Bellen | M27: East | N27: Pham | O27: EPP | P27: 40 | Q27: 880 | R27: 400 | T27: 40597 | U27: Bellen | V27: East | W27: Pham | X27: EPP | Y27: 40 | Z27: 880 | AA27: 400 | AD27: 40597 | AE27: Bellen | AF27: East | AG27: Pham | AH27: EPP | AI27: 40 | AJ27: 880 | AK27: 400 | AM27: EPP Total | AO27: 47 | CD27: ET | CE27: Carlota | CF27: 1357 | CG27: 1357
A28: 40560 | B28: Quad | C28: MidWest | D28: Chin | E28: EPP | F28: 61 | G28: 1647 | H28: 885 | I28: =LEFT(B28,3) -> Qua | K28: 40560 | L28: Quad | M28: MidWest | N28: Chin | O28: EPP | P28: 61 | Q28: 1647 | R28: 885 | T28: 40560 | U28: Quad | V28: MidWest | W28: Chin | X28: EPP | Y28: 61 | Z28: 1647 | AA28: 885 | AD28: 40560 | AE28: Quad | AF28: MidWest | AG28: Chin | AH28: EPP | AI28: 61 | AJ28: 1647 | AK28: 885 | AM28: ET | AN28: Chin | AO28: 59 | CE28: Sunshine | CF28: 228 | CG28: 228
A29: 40563 | B29: Carlota | C29: East | D29: Chin | E29: ET | F29: 59 | G29: 1357 | H29: 649 | I29: =LEFT(B29,3) -> Car | K29: 40563 | L29: Carlota | M29: East | N29: Chin | O29: ET | P29: 59 | Q29: 1357 | R29: 649 | T29: 40563 | U29: Carlota | V29: East | W29: Chin | X29: ET | Y29: 59 | Z29: 1357 | AA29: 649 | AD29: 40563 | AE29: Carlota | AF29: East | AG29: Chin | AH29: ET | AI29: 59 | AJ29: 1357 | AK29: 649 | AN29: Franks | AO29: 12 | CD29: ET Total | CF29: 228 | CG29: 1357
A30: 40593 | B30: Carlota | C30: East | D30: Chin | E30: ET | F30: 59 | G30: 1357 | H30: 649 | I30: =LEFT(B30,3) -> Car | K30: 40593 | L30: Carlota | M30: East | N30: Chin | O30: ET | P30: 59 | Q30: 1357 | R30: 649 | T30: 40593 | U30: Carlota | V30: East | W30: Chin | X30: ET | Y30: 59 | Z30: 1357 | AA30: 649 | AD30: 40593 | AE30: Carlota | AF30: East | AG30: Chin | AH30: ET | AI30: 59 | AJ30: 1357 | AK30: 649 | AM30: ET Total | AO30: 35.5 | CD30: FM | CE30: Bellen | CF30: 154 | CG30: 154
A31: 40548 | B31: Sunshine | C31: West | D31: Franks | E31: ET | F31: 12 | G31: 228 | H31: 96 | I31: =LEFT(B31,3) -> Sun | K31: 40548 | L31: Sunshine | M31: West | N31: Franks | O31: ET | P31: 12 | Q31: 228 | R31: 96 | T31: 40548 | U31: Sunshine | V31: West | W31: Franks | X31: ET | Y31: 12 | Z31: 228 | AA31: 96 | AD31: 40548 | AE31: Sunshine | AF31: West | AG31: Franks | AH31: ET | AI31: 12 | AJ31: 228 | AK31: 96 | AM31: FM | AN31: Chin | AO31: 40 | CE31: Carlota | CF31: 460 | CG31: 1196
A32: 40593 | B32: Sunshine | C32: West | D32: Franks | E32: ET | F32: 12 | G32: 228 | H32: 96 | I32: =LEFT(B32,3) -> Sun | K32: 40593 | L32: Sunshine | M32: West | N32: Franks | O32: ET | P32: 12 | Q32: 228 | R32: 96 | T32: 40593 | U32: Sunshine | V32: West | W32: Franks | X32: ET | Y32: 12 | Z32: 228 | AA32: 96 | AD32: 40593 | AE32: Sunshine | AF32: West | AG32: Franks | AH32: ET | AI32: 12 | AJ32: 228 | AK32: 96 | AN32: Franks | AO32: 29 | CE32: Quad | CF32: 783 | CG32: 1566
A33: 40553 | B33: Bellen | C33: MidWest | D33: Gault | E33: FM | F33: 7 | G33: 154 | H33: 70 | I33: =LEFT(B33,3) -> Bel | K33: 40553 | L33: Bellen | M33: MidWest | N33: Gault | O33: FM | P33: 7 | Q33: 154 | R33: 70 | T33: 40553 | U33: Bellen | V33: MidWest | W33: Gault | X33: FM | Y33: 7 | Z33: 154 | AA33: 70 | AD33: 40553 | AE33: Bellen | AF33: MidWest | AG33: Gault | AH33: FM | AI33: 7 | AJ33: 154 | AK33: 70 | AN33: Gault | AO33: 7 | CE33: Sunset | CF33: 1302 | CG33: 1302
A34: 40546 | B34: Carlota | C34: MidWest | D34: Chin | E34: FM | F34: 20 | G34: 460 | H34: 220 | I34: =LEFT(B34,3) -> Car | K34: 40546 | L34: Carlota | M34: MidWest | N34: Chin | O34: FM | P34: 20 | Q34: 460 | R34: 220 | T34: 40546 | U34: Carlota | V34: MidWest | W34: Chin | X34: FM | Y34: 20 | Z34: 460 | AA34: 220 | AD34: 40546 | AE34: Carlota | AF34: MidWest | AG34: Chin | AH34: FM | AI34: 20 | AJ34: 460 | AK34: 220 | AN34: Pham | AO34: 38 | CE34: Sunshine | CF34: 722 | CG34: 722
A35: 40591 | B35: Carlota | C35: MidWest | D35: Chin | E35: FM | F35: 20 | G35: 460 | H35: 220 | I35: =LEFT(B35,3) -> Car | K35: 40591 | L35: Carlota | M35: MidWest | N35: Chin | O35: FM | P35: 20 | Q35: 460 | R35: 220 | T35: 40591 | U35: Carlota | V35: MidWest | W35: Chin | X35: FM | Y35: 20 | Z35: 460 | AA35: 220 | AD35: 40591 | AE35: Carlota | AF35: MidWest | AG35: Chin | AH35: FM | AI35: 20 | AJ35: 460 | AK35: 220 | AN35: Smith | AO35: 52 | CD35: FM Total | CF35: 154 | CG35: 1566
A36: 40556 | B36: Carlota | C36: South | D36: Smith | E36: FM | F36: 52 | G36: 1196 | H36: 572 | I36: =LEFT(B36,3) -> Car | K36: 40556 | L36: Carlota | M36: South | N36: Smith | O36: FM | P36: 52 | Q36: 1196 | R36: 572 | T36: 40556 | U36: Carlota | V36: South | W36: Smith | X36: FM | Y36: 52 | Z36: 1196 | AA36: 572 | AD36: 40556 | AE36: Carlota | AF36: South | AG36: Smith | AH36: FM | AI36: 52 | AJ36: 1196 | AK36: 572 | AM36: FM Total | AO36: 35.75 | CD36: FRED | CE36: Bellen | CF36: 5000 | CG36: 5000
A37: 40564 | B37: Quad | C37: East | D37: Chin | E37: FM | F37: 58 | G37: 1566 | H37: 841 | I37: =LEFT(B37,3) -> Qua | K37: 40564 | L37: Quad | M37: East | N37: Chin | O37: FM | P37: 58 | Q37: 1566 | R37: 841 | T37: 40564 | U37: Quad | V37: East | W37: Chin | X37: FM | Y37: 58 | Z37: 1566 | AA37: 841 | AD37: 40564 | AE37: Quad | AF37: East | AG37: Chin | AH37: FM | AI37: 58 | AJ37: 1566 | AK37: 841 | AM37: FRED | AN37: Pham | AO37: 61 | CE37: Sunshine | CF37: 969 | CG37: 969
A38: 40565 | B38: Quad | C38: South | D38: Franks | E38: FM | F38: 29 | G38: 783 | H38: 421 | I38: =LEFT(B38,3) -> Qua | K38: 40565 | L38: Quad | M38: South | N38: Franks | O38: FM | P38: 29 | Q38: 783 | R38: 421 | T38: 40565 | U38: Quad | V38: South | W38: Franks | X38: FM | Y38: 29 | Z38: 783 | AA38: 421 | AD38: 40565 | AE38: Quad | AF38: South | AG38: Franks | AH38: FM | AI38: 29 | AJ38: 783 | AK38: 421 | AN38: Smith | AO38: 51 | CD38: FRED Total | CF38: 969 | CG38: 5000
A39: 40571 | B39: Sunset | C39: West | D39: Chin | E39: FM | F39: 62 | G39: 1302 | H39: 574 | I39: =LEFT(B39,3) -> Sun | K39: 40571 | L39: Sunset | M39: West | N39: Chin | O39: FM | P39: 62 | Q39: 1302 | R39: 574 | T39: 40571 | U39: Sunset | V39: West | W39: Chin | X39: FM | Y39: 62 | Z39: 1302 | AA39: 574 | AD39: 40571 | AE39: Sunset | AF39: West | AG39: Chin | AH39: FM | AI39: 62 | AJ39: 1302 | AK39: 574 | AM39: FRED Total | AO39: 54.333333 | CD39: HHH | CE39: Carlota | CF39: 276 | CG39: 276
A40: 40546 | B40: Sunshine | C40: East | D40: Pham | E40: FM | F40: 38 | G40: 722 | H40: 304 | I40: =LEFT(B40,3) -> Sun | K40: 40546 | L40: Sunshine | M40: East | N40: Pham | O40: FM | P40: 38 | Q40: 722 | R40: 304 | T40: 40546 | U40: Sunshine | V40: East | W40: Pham | X40: FM | Y40: 38 | Z40: 722 | AA40: 304 | AD40: 40546 | AE40: Sunshine | AF40: East | AG40: Pham | AH40: FM | AI40: 38 | AJ40: 722 | AK40: 304 | AM40: HHH | AN40: Franks | AO40: 27.666667 | CE40: Sunset | CF40: 273 | CG40: 273
...

Sheet Q2
A3: Telugu | B3: English | C3: Hindi | D3: Maths | E3: Total | F3: Gender | G3: PASS/FAIL
A4: 72 | B4: 70 | C4: 60 | D4: 61 | E4: 263 | F4: M | G4: =IF(AND(A4>=40,B4>=40,C4>=40,D4>=40),"PASS","FAIL") -> PASS
A5: 97 | B5: 65 | C5: 87 | D5: 92 | E5: 341 | F5: M | G5: =IF(AND(A5>=40,B5>=40,C5>=40,D5>=40),"PASS","FAIL") -> PASS | J5: All students are Each subjects above =40 then pass either fail.
A6: 95 | B6: 95 | C6: 100 | D6: 86 | E6: 376 | F6: M | G6: =IF(AND(A6>=40,B6>=40,C6>=40,D6>=40),"PASS","FAIL") -> PASS
A7: 81 | B7: 74 | C7: 89 | D7: 81 | E7: 325 | F7: F | G7: =IF(AND(A7>=40,B7>=40,C7>=40,D7>=40),"PASS","FAIL") -> PASS
A8: 81 | B8: 68 | C8: 63 | D8: 82 | E8: 294 | F8: F | G8: =IF(AND(A8>=40,B8>=40,C8>=40,D8>=40),"PASS","FAIL") -> PASS
A9: 91 | B9: 65 | C9: 66 | D9: 61 | E9: 283 | F9: M | G9: =IF(AND(A9>=40,B9>=40,C9>=40,D9>=40),"PASS","FAIL") -> PASS
A10: 92 | B10: 79 | C10: 98 | D10: 61 | E10: 330 | F10: F | G10: =IF(AND(A10>=40,B10>=40,C10>=40,D10>=40),"PASS","FAIL") -> PASS
A11: 74 | B11: 60 | C11: 94 | D11: 97 | E11: 325 | F11: M | G11: =IF(AND(A11>=40,B11>=40,C11>=40,D11>=40),"PASS","FAIL") -> PASS
A12: 81 | B12: 70 | C12: 67 | D12: 85 | E12: 303 | F12: M | G12: =IF(AND(A12>=40,B12>=40,C12>=40,D12>=40),"PASS","FAIL") -> PASS
A13: 83 | B13: 62 | C13: 93 | D13: 100 | E13: 338 | F13: M | G13: =IF(AND(A13>=40,B13>=40,C13>=40,D13>=40),"PASS","FAIL") -> PASS
A14: 76 | B14: 70 | C14: 89 | D14: 60 | E14: 295 | F14: F | G14: =IF(AND(A14>=40,B14>=40,C14>=40,D14>=40),"PASS","FAIL") -> PASS
A15: 67 | B15: 60 | C15: 69 | D15: 68 | E15: 264 | F15: F | G15: =IF(AND(A15>=40,B15>=40,C15>=40,D15>=40),"PASS","FAIL") -> PASS
A16: 100 | B16: 68 | C16: 74 | D16: 100 | E16: 342 | F16: M | G16: =IF(AND(A16>=40,B16>=40,C16>=40,D16>=40),"PASS","FAIL") -> PASS
A17: 82 | B17: 70 | C17: 70 | D17: 94 | E17: 316 | F17: F | G17: =IF(AND(A17>=40,B17>=40,C17>=40,D17>=40),"PASS","FAIL") -> PASS
A18: 89 | B18: 61 | C18: 83 | D18: 99 | E18: 332 | F18: M | G18: =IF(AND(A18>=40,B18>=40,C18>=40,D18>=40),"PASS","FAIL") -> PASS

Sheet Q3
A1: Q) Below 250 failor grade D,250 to 300 grade C,301 to 350 grade Band above 350 Grade A it's based on total marks
M2: USING NESTED FORMULA
A4: Telugu | B4: English | C4: Hindi | D4: Maths | E4: Total | F4: Gender | G4: GRADE
A5: 72 | B5: 70 | C5: 60 | D5: 61 | E5: 263 | F5: M | G5: =IF(E5<=250,"D",IF(E5<=300,"C",IF(E5<=350,"B","A"))) -> C
A6: 97 | B6: 65 | C6: 87 | D6: 92 | E6: 341 | F6: M | G6: =IF(E6<=250,"D",IF(E6<=300,"C",IF(E6<=350,"B","A"))) -> B | L6: 250 | M6: d
A7: 95 | B7: 95 | C7: 100 | D7: 86 | E7: 376 | F7: M | G7: =IF(E7<=250,"D",IF(E7<=300,"C",IF(E7<=350,"B","A"))) -> A | L7: 251-300 | M7: c
A8: 81 | B8: 74 | C8: 89 | D8: 81 | E8: 325 | F8: F | G8: =IF(E8<=250,"D",IF(E8<=300,"C",IF(E8<=350,"B","A"))) -> B | L8: 301-350 | M8: b
A9: 81 | B9: 68 | C9: 63 | D9: 82 | E9: 294 | F9: F | G9: =IF(E9<=250,"D",IF(E9<=300,"C",IF(E9<=350,"B","A"))) -> C | L9: >350 | M9: a
A10: 91 | B10: 65 | C10: 66 | D10: 61 | E10: 283 | F10: M | G10: =IF(E10<=250,"D",IF(E10<=300,"C",IF(E10<=350,"B","A"))) -> C
A11: 92 | B11: 79 | C11: 98 | D11: 61 | E11: 330 | F11: F | G11: =IF(E11<=250,"D",IF(E11<=300,"C",IF(E11<=350,"B","A"))) -> B
A12: 74 | B12: 60 | C12: 94 | D12: 97 | E12: 325 | F12: M | G12: =IF(E12<=250,"D",IF(E12<=300,"C",IF(E12<=350,"B","A"))) -> B
A13: 81 | B13: 70 | C13: 67 | D13: 85 | E13: 303 | F13: M | G13: =IF(E13<=250,"D",IF(E13<=300,"C",IF(E13<=350,"B","A"))) -> B
A14: 83 | B14: 62 | C14: 93 | D14: 100 | E14: 338 | F14: M | G14: =IF(E14<=250,"D",IF(E14<=300,"C",IF(E14<=350,"B","A"))) -> B
A15: 76 | B15: 70 | C15: 89 | D15: 60 | E15: 295 | F15: F | G15: =IF(E15<=250,"D",IF(E15<=300,"C",IF(E15<=350,"B","A"))) -> C
A16: 67 | B16: 60 | C16: 69 | D16: 68 | E16: 264 | F16: F | G16: =IF(E16<=250,"D",IF(E16<=300,"C",IF(E16<=350,"B","A"))) -> C
A17: 100 | B17: 68 | C17: 74 | D17: 100 | E17: 342 | F17: M | G17: =IF(E17<=250,"D",IF(E17<=300,"C",IF(E17<=350,"B","A"))) -> B
A18: 82 | B18: 70 | C18: 70 | D18: 94 | E18: 316 | F18: F | G18: =IF(E18<=250,"D",IF(E18<=300,"C",IF(E18<=350,"B","A"))) -> B
A19: 89 | B19: 61 | C19: 83 | D19: 99 | E19: 332 | F19: M | G19: =IF(E19<=250,"D",IF(E19<=300,"C",IF(E19<=350,"B","A"))) -> B
A20: 93 | B20: 87 | C20: 78 | D20: 75 | E20: 333 | F20: F | G20: =IF(E20<=250,"D",IF(E20<=300,"C",IF(E20<=350,"B","A"))) -> B
A21: 71 | B21: 71 | C21: 88 | D21: 77 | E21: 307 | F21: F | G21: =IF(E21<=250,"D",IF(E21<=300,"C",IF(E21<=350,"B","A"))) -> B
... A30: 89 | B30: 72 | C30: 73 | D30: 81 | E30: 315 | F30: M | G30: =IF(E30<=250,"D",IF(E30<=300,"C",IF(E30<=350,"B","A"))) -> B

Sheet Q4
A2: Q1) how many records are there in Date column
A3: Q2) how many records are there in Region column
A4: Q3) how many records are there in Salesrep column
A5: Q4) total sales
A7: Date | B7: Product | C7: Region | D7: Nationality | E7: SalesRep | F7: Customer | G7: Sales | I7: count | J7: counta | K7: count blank | L7: sum
A8: 40553 | B8: Carlota | C8: East | D8: Indian | E8: Pham | F8: Anirudh | G8: 1449 | H8: Date | I8: =COUNT(A8:A142) -> 135 | J8: =COUNTA(A8:A142) -> 135 | K8: =COUNTBLANK(A8:A142) -> 0
A9: 40544 | B9: Quad | C9: East | D9: Indian | F9: Abishek | G9: 432 | H9: Region | I9: =COUNT(C8:C142) -> 0 | J9: =COUNTA(C8:C142) -> 135 | K9: =COUNTBLANK(C8:C142) -> 0
A10: 40561 | B10: Sunshine | C10: East | D10: Indian | E10: Franks | F10: RAGHAV | G10: 456 | H10: salesrep | I10: =COUNT(E8:E142) -> 0 | J10: =COUNTA(E8:E1048576) -> 132
A11: 40606 | B11: Sunshine | C11: East | D11: Indian | E11: Franks | F11: SEETHA | G11: 456 | H11: total sales | I11: =COUNT(G8:G142) -> 135 | J11: =COUNTA(G8:G142) -> 135 | K11: =COUNTBLANK(G8:G142) -> 0 | L11: =SUM(G8:G142) -> 107605
A12: 40572 | B12: Bellen | C12: East | D12: Indian | E12: Chin | F12: Kavitha | G12: 1100 | J12: count calculate only text number in selected range
A13: 40565 | B13: Bellen | C13: West | D13: Indian | E13: Pham | F13: AST | G13: 1166 | J13: counta Acalculated both text and numeric values in selected range
A14: 40610 | B14: Bellen | C14: West | D14: Indian | E14: Pham | F14: AST | G14: 1166 | J14: countblanks count only blanks in selected range
A15: 40545 | B15: Quad | C15: West | D15: Indian | E15: Pham | F15: Santhosh | G15: 810
A16: 40558 | B16: Sunset | C16: East | D16: Indian | E16: Gault | F16: AST | G16: 1323
A17: 40561 | B17: Sunshine | C17: West | D17: Indian | F17: Yasvanth | G17: 152
A18: 40591 | B18: Sunshine | C18: West | D18: Indian | E18: Sioux | F18: AST | G18: 152
A19: 40567 | B19: Carlota | C19: MidWest | D19: Foreigner | E19: Franks | F19: BBT | G19: 299
A20: 40612 | B20: Carlota | C20: MidWest | D20: Foreigner | E20: Franks | F20: BBT | G20: 299
A21: 40554 | B21: Quad | C21: East | D21: Indian | E21: Smith | F21: BBT | G21: 1323
A22: 40547 | B22: Sunset | C22: MidWest | D22: Foreigner | E22: Sioux | F22: BBT | G22: 609
A23: 40561 | B23: Bellen | C23: East | D23: Indian | F23: DFGH | G23: 440
A24: 40566 | B24: Bellen | C24: East | D24: Indian | E24: Gault | F24: DFGH | G24: 198
A25: 40611 | B25: Bellen | C25: East | D25: Indian | E25: Gault | F25: DFGH | G25: 198
A26: 40569 | B26: Sunset | C26: South | D26: Foreigner | E26: Sioux | F26: DFGH | G26: 924
A27: 40561 | B27: Bellen | C27: East | D27: Indian | E27: Pham | F27: DFR | G27: 1298
A28: 40553 | B28: Quad | C28: East | D28: Indian | E28: Smith | F28: DFR | G28: 459
A29: 40564 | B29: Sunshine | C29: MidWest | D29: Foreigner | E29: Pham | F29: DFR | G29: 437
A30: 40573 | B30: Sunshine | C30: West | D30: Indian | E30: Gault | F30: DFR | G30: 931
A31: 40552 | B31: Bellen | C31: East | D31: Indian | E31: Pham | F31: EPP | G31: 880
A32: 40597 | B32: Bellen | C32: East | D32: Indian | E32: Pham | F32: EPP | G32: 880
A33: 40560 | B33: Quad | C33: MidWest | D33: Foreigner | E33: Chin | F33: EPP | G33: 1647
A34: 40563 | B34: Carlota | C34: East | D34: Indian | E34: Chin | F34: ET | G34: 1357
A35: 40593 | B35: Carlota | C35: East | D35: Indian | E35: Chin | F35: ET | G35: 1357
... A142: 40571 | B142: Sunset | C142: East | D142: Indian | E142: Smith | F142: ZAT | G142: 756

Sheet Q5
B2: 1st | C2: Last
B3: 2 Letters | C3: 3 Letters
A4: Customer | B4: Left | C4: Right | D4: Upper | E4: Lower | F4: Proper
A5: Anirudh | B5: =LEFT(A5,2) -> An | C5: =RIGHT(A5,3) -> udh | D5: =UPPER(A5) -> ANIRUDH | E5: =LOWER(A5) -> anirudh | F5: =PROPER(A5) -> Anirudh
A6: Abishek | B6: =LEFT(A6,2) -> Ab | C6: =RIGHT(A6,3) -> hek | D6: =UPPER(A6) -> ABISHEK | E6: =LOWER(A6) -> abishek | F6: =PROPER(A6) -> Abishek
A7: RAGHAV | B7: =LEFT(A7,2) -> RA | C7: =RIGHT(A7,3) -> HAV | D7: =UPPER(A7) -> RAGHAV | E7: =LOWER(A7) -> raghav | F7: =PROPER(A7) -> Raghav
A8: SEETHA | B8: =LEFT(A8,2) -> SE | C8: =RIGHT(A8,3) -> THA | D8: =UPPER(A8) -> SEETHA | E8: =LOWER(A8) -> seetha | F8: =PROPER(A8) -> Seetha | J8: it will depend functions all in customer ID
A9: Kavitha | B9: =LEFT(A9,2) -> Ka | C9: =RIGHT(A9,3) -> tha | D9: =UPPER(A9) -> KAVITHA | E9: =LOWER(A9) -> kavitha | F9: =PROPER(A9) -> Kavitha
A10: AST | B10: =LEFT(A10,2) -> AS | C10: =RIGHT(A10,3) -> AST | D10: =UPPER(A10) -> AST | E10: =LOWER(A10) -> ast | F10: =PROPER(A10) -> Ast
A11: AST | B11: =LEFT(A11,2) -> AS | C11: =RIGHT(A11,3) -> AST | D11: =UPPER(A11) -> AST | E11: =LOWER(A11) -> ast | F11: =PROPER(A11) -> Ast
A12: Santhosh | B12: =LEFT(A12,2) -> Sa | C12: =RIGHT(A12,3) -> osh | D12: =UPPER(A12) -> SANTHOSH | E12: =LOWER(A12) -> santhosh | F12: =PROPER(A12) -> Santhosh
A13: AST | B13: =LEFT(A13,2) -> AS | C13: =RIGHT(A13,3) -> AST | D13: =UPPER(A13) -> AST | E13: =LOWER(A13) -> ast | F13: =PROPER(A13) -> Ast
A14: Yasvanth | B14: =LEFT(A14,2) -> Ya | C14: =RIGHT(A14,3) -> nth | D14: =UPPER(A14) -> YASVANTH | E14: =LOWER(A14) -> yasvanth | F14: =PROPER(A14) -> Yasvanth
A15: AST | B15: =LEFT(A15,2) -> AS | C15: =RIGHT(A15,3) -> AST | D15: =UPPER(A15) -> AST | E15: =LOWER(A15) -> ast | F15: =PROPER(A15) -> Ast
A16: BBT | B16: =LEFT(A16,2) -> BB | C16: =RIGHT(A16,3) -> BBT | D16: =UPPER(A16) -> BBT | E16: =LOWER(A16) -> bbt | F16: =PROPER(A16) -> Bbt
A17: BBT | B17: =LEFT(A17,2) -> BB | C17: =RIGHT(A17,3) -> BBT | D17: =UPPER(A17) -> BBT | E17: =LOWER(A17) -> bbt | F17: =PROPER(A17) -> Bbt
A18: BBT | B18: =LEFT(A18,2) -> BB | C18: =RIGHT(A18,3) -> BBT | D18: =UPPER(A18) -> BBT | E18: =LOWER(A18) -> bbt | F18: =PROPER(A18) -> Bbt
A19: BBT | B19: =LEFT(A19,2) -> BB | C19: =RIGHT(A19,3) -> BBT | D19: =UPPER(A19) -> BBT | E19: =LOWER(A19) -> bbt | F19: =PROPER(A19) -> Bbt
A20: DFGH | B20: =LEFT(A20,2) -> DF | C20: =RIGHT(A20,3) -> FGH | D20: =UPPER(A20) -> DFGH | E20: =LOWER(A20) -> dfgh | F20: =PROPER(A20) -> Dfgh
... A139: ZAT | B139: =LEFT(A139,2) -> ZA | C139: =RIGHT(A139,3) -> ZAT | D139: =UPPER(A139) -> ZAT | E139: =LOWER(A139) -> zat | F139: =PROPER(A139) -> Zat

Sheet Q6
A1: Date | B1: Product | C1: Region | D1: SalesRep | E1: Customer | F1: Units | G1: Sales | H1: Discount | I1: UNIQUE LIST | K1: Average | M1: 1) | T1: 3) | X1: 5) | AC1: Date | AD1: Product | AE1: Region | AF1: SalesRep | AG1: Customer | AH1: Units | AI1: Sales | AJ1: Discount | AK1: UNIQUE LIST
A2: 40553 | B2: Carlota | C2: East | D2: Pham | E2: AA | F2: 63 | G2: 1449 | H2: 693 | I2: {=_xlfn.UNIQUE(E2:E136)} -> AA | K2: =AVERAGE(H2:H136) -> 366.2963 | M2: Product | N2: Sum of Sales | T2: Customer | U2: Average of Sales | X2: Product | Y2: Min of Sales | Z2: Max of Sales2 | AC2: 40553 | AD2: Bellen | AE2: West | AF2: Pham | AG2: AA | AH2: 63 | AI2: 114 | AJ2: 693 | AK2: {=_xlfn.UNIQUE(AG2:AG136)} -> AA
A3: 40544 | B3: Quad | C3: East | D3: Sioux | E3: AA | F3: 16 | G3: 432 | H3: 232 | I3: AST | M3: Bellen | N3: 25218 | T3: AA | U3: 698.25 | X3: Bellen | Y3: 132 | Z3: 5000 | AC3: 40544 | AD3: Bellen | AE3: West | AF3: Sioux | AG3: AA | AH3: 16 | AI3: 114 | AJ3: 232 | AK3: AST
A4: 40561 | B4: Sunshine | C4: East | D4: Franks | E4: AA | F4: 24 | G4: 456 | H4: 192 | I4: BBT | K4: 1 | L4: PRODUCT WISE TOTAL SALES | M4: Carlota | N4: 19159 | T4: AST | U4: 838.42857 | X4: Carlota | Y4: 230 | Z4: 1449 | AC4: 40561 | AD4: Bellen | AE4: West | AF4: Franks | AG4: AA | AH4: 24 | AI4: 132 | AJ4: 192 | AK4: BBT
A5: 40606 | B5: Sunshine | C5: East | D5: Franks | E5: AA | F5: 24 | G5: 456 | H5: 192 | I5: DFGH | K5: 2 | L5: REGION WISE SALES REP, TOTAL UNITS | M5: Quad | N5: 30834 | T5: BBT | U5: 632.5 | X5: Quad | Y5: 270 | Z5: 1755 | AC5: 40606 | AD5: Bellen | AE5: West | AF5: Franks | AG5: AA | AH5: 24 | AI5: 132 | AJ5: 192 | AK5: DFGH
A6: 40572 | B6: Bellen | C6: East | D6: Chin | E6: AST | F6: 50 | G6: 1100 | H6: 500 | I6: DFR | K6: 3 | L6: CUSTOMER WISE AVERAGE SALES | M6: Sunset | N6: 14553 | T6: DFGH | U6: 440 | X6: Sunset | Y6: 252 | Z6: 1323 | AC6: 40572 | AD6: Bellen | AE6: West | AF6: Chin | AG6: AST | AH6: 50 | AI6: 152 | AJ6: 500 | AK6: DFR
A7: 40565 | B7: Bellen | C7: West | D7: Pham | E7: AST | F7: 53 | G7: 1166 | H7: 530 | I7: EPP | K7: 4 | L7: PERCENTAGE OF DISCOUNT BY REGION | M7: Sunshine | N7: 17841 | T7: DFR | U7: 781.25 | X7: Sunshine | Y7: 114 | Z7: 1216 | AC7: 40565 | AD7: Bellen | AE7: West | AF7: Pham | AG7: AST | AH7: 53 | AI7: 152 | AJ7: 530 | AK7: EPP
A8: 40610 | B8: Bellen | C8: West | D8: Pham | E8: AST | F8: 53 | G8: 1166 | H8: 530 | I8: ET | K8: 5 | L8: MIN SALES AMOUNT,MAX SALES AMOUNT BY PRODUCT | M8: (blank) | T8: EPP | U8: 1135.6667 | X8: (blank) | AC8: 40610 | AD8: Bellen | AE8: West | AF8: Pham | AG8: AST | AH8: 53 | AI8: 152 | AJ8: 530 | AK8: ET
A9: 40545 | B9: Quad | C9: West | D9: Pham | E9: AST | F9: 30 | G9: 810 | H9: 435 | I9: FM | K9: 6 | L9: CREATE UNIQUE LIST OF COUSTOMERS | M9: Grand Total | N9: 107605 | T9: ET | U9: 792.5 | X9: Grand Total | Y9: 114 | Z9: 5000 | AC9: 40545 | AD9: Bellen | AE9: West | AF9: Pham | AG9: AST | AH9: 30 | AI9: 154 | AJ9: 435 | AK9: FM
A10: 40558 | B10: Sunset | C10: East | D10: Gault | E10: AST | F10: 63 | G10: 1323 | H10: 583 | I10: FRED | K10: 7 | L10: HIGHLIGHT THE ALL EAST REGION | T10: FM | U10: 830.375 | AC10: 40558 | AD10: Bellen | AE10: West | AF10: Gault | AG10: AST | AH10: 63 | AI10: 154 | AJ10: 583 | AK10: FRED
A11: 40561 | B11: Sunshine | C11: West | D11: Sioux | E11: AST | F11: 8 | G11: 152 | H11: 64 | I11: HHH | K11: 8 | L11: HIGHLIGHT THE DUPLICATE DATES | M11: 2) | T11: FRED | U11: 2312.6667 | X11: 4) | AC11: 40561 | AD11: Bellen | AE11: West | AF11: Sioux | AG11: AST | AH11: 8 | AI11: 198 | AJ11: 64 | AK11: HHH
A12: 40591 | B12: Sunshine | C12: West | D12: Sioux | E12: AST | F12: 8 | G12: 152 | H12: 64 | I12: HII | K12: 9 | L12: HIGHLIGHTS ABOVE AVERAGE DISCOUNT COLUMN | M12: Sum of Units | N12: Region | T12: HHH | U12: 486.5 | X12: Region | Y12: PERCENTAGE OF DISCOUNT | AC12: 40591 | AD12: Bellen | AE12: West | AF12: Sioux | AG12: AST | AH12: 8 | AI12: 198 | AJ12: 64 | AK12: HII
A13: 40567 | B13: Carlota | C13: MidWest | D13: Franks | E13: BBT | F13: 13 | G13: 299 | H13: 143 | I13: ITTW | K13: 10 | L13: REGION Z to A,PRODUCT A to Z,SALES INCREASING ORDERS | M13: SalesRep | N13: East | O13: MidWest | P13: South | Q13: West | R13: (blank) | S13: Grand Total | T13: HII | U13: 1370.25 | X13: East | Y13: 0.32212336 | AC13: 40567 | AD13: Bellen | AE13: West | AF13: Franks | AG13: BBT | AH13: 13 | AI13: 209 | AJ13: 143 | AK13: ITTW
A14: 40612 | B14: Carlota | C14: MidWest | D14: Franks | E14: BBT | F14: 13 | G14: 299 | H14: 143 | I14: ITW | M14: Chin | N14: 243 | O14: 247 | P14: 112 | Q14: 98 | S14: 700 | T14: ITTW | U14: 1380 | X14: MidWest | Y14: 0.18394338 | AC14: 40612 | AD14: Bellen | AE14: West | AF14: Franks | AG14: BBT | AH14: 13 | AI14: 209 | AJ14: 143 | AK14: ITW
A15: 40554 | B15: Quad | C15: East | D15: Smith | E15: BBT | F15: 49 | G15: 1323 | H15: 711 | I15: JAQ | M15: Franks | N15: 428 | O15: 130 | P15: 163 | Q15: 144 | S15: 865 | T15: ITW | U15: 666.75 | X15: South | Y15: 0.24489383 | AC15: 40554 | AD15: Bellen | AE15: West | AF15: Smith | AG15: BBT | AH15: 49 | AI15: 220 | AJ15: 711 | AK15: JAQ
A16: 40547 | B16: Sunset | C16: MidWest | D16: Sioux | E16: BBT | F16: 29 | G16: 609 | H16: 268 | I16: KBTB | M16: Gault | N16: 216 | O16: 78 | P16: 160 | Q16: 178 | S16: 632 | T16: JAQ | U16: 590.5 | X16: West | Y16: 0.24903943 | AC16: 40547 | AD16: Bellen | AE16: West | AF16: Sioux | AG16: BBT | AH16: 29 | AI16: 228 | AJ16: 268 | AK16: KBTB
A17: 40561 | B17: Bellen | C17: East | D17: Franks | E17: DFGH | F17: 20 | G17: 440 | H17: 200 | I17: KPSA | M17: Pham | N17: 262 | O17: 153 | P17: 93 | Q17: 391 | S17: 899 | T17: KBTB | U17: 1083.6667 | X17: (blank) | Y17: 0 | AC17: 40561 | AD17: Bellen | AE17: West | AF17: Franks | AG17: DFGH | AH17: 20 | AI17: 228 | AJ17: 200 | AK17: KPSA
A18: 40566 | B18: Bellen | C18: East | D18: Gault | E18: DFGH | F18: 9 | G18: 198 | H18: 90 | I18: LOP | M18: Sioux | N18: 94 | O18: 163 | P18: 298 | Q18: 191 | S18: 746 | T18: KPSA | U18: 394 | X18: Grand Total | Y18: 1 | AC18: 40566 | AD18: Bellen | AE18: West | AF18: Gault | AG18: DFGH | AH18: 9 | AI18: 230 | AJ18: 90 | AK18: LOP
A19: 40611 | B19: Bellen | C19: East | D19: Gault | E19: DFGH | F19: 9 | G19: 198 | H19: 90 | I19: MBG | M19: Smith | N19: 161 | O19: 147 | P19: 318 | Q19: 119 | S19: 745 | T19: LOP | U19: 345 | AC19: 40611 | AD19: Bellen | AE19: West | AF19: Gault | AG19: DFGH | AH19: 9 | AI19: 242 | AJ19: 90 | AK19: MBG
A20: 40569 | B20: Sunset | C20: South | D20: Sioux | E20: DFGH | F20: 44 | G20: 924 | H20: 407 | I20: MNGD | M20: (blank) | T20: MBG | U20: 777 | AC20: 40569 | AD20: Bellen | AE20: West | AF20: Sioux | AG20: DFGH | AH20: 44 | AI20: 252 | AJ20: 407 | AK20: MNGD
A21: 40561 | B21: Bellen | C21: East | D21: Pham | E21: DFR | F21: 59 | G21: 1298 | H21: 590 | I21: PCC | M21: Grand Total | N21: 1404 | O21: 918 | P21: 1144 | Q21: 1121 | S21: 4587 | T21: MNGD | U21: 655 | AC21: 40561 | AD21: Bellen | AE21: West | AF21: Pham | AG21: DFR | AH21: 59 | AI21: 270 | AJ21: 590 | AK21: PCC
A22: 40553 | B22: Quad | C22: East | D22: Smith | E22: DFR | F22: 17 | G22: 459 | H22: 247 | I22: PLOT | T22: PCC | U22: 726.61538 | AC22: 40553 | AD22: Bellen | AE22: West | AF22: Smith | AG22: DFR | AH22: 17 | AI22: 270 | AJ22: 247 | AK22: PLOT
A23: 40564 | B23: Sunshine | C23: MidWest | D23: Pham | E23: DFR | F23: 23 | G23: 437 | H23: 184 | I23: PSA | T23: PLOT | U23: 661 | AC23: 40564 | AD23: Bellen | AE23: West | AF23: Pham | AG23: DFR | AH23: 23 | AI23: 270 | AJ23: 184 | AK23: PSA
A24: 40573 | B24: Sunshine | C24: West | D24: Gault | E24: DFR | F24: 49 | G24: 931 | H24: 392 | I24: QT | T24: PSA | U24: 612.83333 | AC24: 40573 | AD24: Bellen | AE24: West | AF24: Gault | AG24: DFR | AH24: 49 | AI24: 273 | AJ24: 392 | AK24: QT
A25: 40552 | B25: Bellen | C25: East | D25: Pham | E25: EPP | F25: 40 | G25: 880 | H25: 400 | I25: SFWK | T25: QT | U25: 621.28571 | AC25: 40552 | AD25: Bellen | AE25: West | AF25: Pham | AG25: EPP | AH25: 40 | AI25: 276 | AJ25: 400 | AK25: SFWK
A26: 40597 | B26: Bellen | C26: East | D26: Pham | E26: EPP | F26: 40 | G26: 880 | H26: 400 | I26: T | T26: SFWK | U26: 913.33333 | AC26: 40597 | AD26: Bellen | AE26: West | AF26: Pham | AG26: EPP | AH26: 40 | AI26: 276 | AJ26: 400 | AK26: T
A27: 40560 | B27: Quad | C27: MidWest | D27: Chin | E27: EPP | F27: 61 | G27: 1647 | H27: 885 | I27: TRU | T27: T | U27: 971.4 | AC27: 40560 | AD27: Bellen | AE27: West | AF27: Chin | AG27: EPP | AH27: 61 | AI27: 299 | AJ27: 885 | AK27: TRU
A28: 40563 | B28: Carlota | C28: East | D28: Chin | E28: ET | F28: 59 | G28: 1357 | H28: 649 | I28: TTT | T28: TRU | U28: 459.66667 | AC28: 40563 | AD28: Bellen | AE28: West | AF28: Chin | AG28: ET | AH28: 59 | AI28: 299 | AJ28: 649 | AK28: TTT
A29: 40593 | B29: Carlota | C29: East | D29: Chin | E29: ET | F29: 59 | G29: 1357 | H29: 649 | I29: WSD | T29: TTT | U29: 615.25 | AC29: 40593 | AD29: Bellen | AE29: West | AF29: Chin | AG29: ET | AH29: 59 | AI29: 330 | AJ29: 649 | AK29: WSD
A30: 40548 | B30: Sunshine | C30: West | D30: Franks | E30: ET | F30: 12 | G30: 228 | H30: 96 | I30: WT | T30: WSD | U30: 700.75 | AC30: 40548 | AD30: Bellen | AE30: West | AF30: Franks | AG30: ET | AH30: 12 | AI30: 345 | AJ30: 96 | AK30: WT
A31: 40593 | B31: Sunshine | C31: West | D31: Franks | E31: ET | F31: 12 | G31: 228 | H31: 96 | I31: YTR | T31: WT | U31: 425 | AC31: 40593 | AD31: Bellen | AE31: West | AF31: Franks | AG31: ET | AH31: 12 | AI31: 352 | AJ31: 96 | AK31: YTR
A32: 40553 | B32: Bellen | C32: MidWest | D32: Gault | E32: FM | F32: 7 | G32: 154 | H32: 70 | I32: ZAT | T32: YTR | U32: 948.3 | AC32: 40553 | AD32: Bellen | AE32: West | AF32: Gault | AG32: FM | AH32: 7 | AI32: 357 | AJ32: 70 | AK32: ZAT
A33: 40546 | B33: Carlota | C33: MidWest | D33: Chin | E33: FM | F33: 20 | G33: 460 | H33: 220 | T33: ZAT | U33: 756 | AC33: 40546 | AD33: Bellen | AE33: South | AF33: Chin | AG33: FM | AH33: 20 | AI33: 374 | AJ33: 220
A34: 40591 | B34: Carlota | C34: MidWest | D34: Chin | E34: FM | F34: 20 | G34: 460 | H34: 220 | T34: (blank) | AC34: 40591 | AD34: Bellen | AE34: South | AF34: Chin | AG34: FM | AH34: 20 | AI34: 378 | AJ34: 220
A35: 40556 | B35: Carlota | C35: South | D35: Smith | E35: FM | F35: 52 | G35: 1196 | H35: 572 | T35: Grand Total | U35: 797.07407 | AC35: 40556 | AD35: Bellen | AE35: South | AF35: Smith | AG35: FM | AH35: 52 | AI35: 378 | AJ35: 572
A36: 40564 | B36: Quad | C36: East | D36: Chin | E36: FM | F36: 58 | G36: 1566 | H36: 841 | AC36: 40564 | AD36: Carlota | AE36: South | AF36: Chin | AG36: FM | AH36: 58 | AI36: 399 | AJ36: 841
A37: 40565 | B37: Quad | C37: South | D37: Franks | E37: FM | F37: 29 | G37: 783 | H37: 421 | AC37: 40565 | AD37: Carlota | AE37: South | AF37: Franks | AG37: FM | AH37: 29 | AI37: 399 | AJ37: 421
A38: 40571 | B38: Sunset | C38: West | D38: Chin | E38: FM | F38: 62 | G38: 1302 | H38: 574 | AC38: 40571 | AD38: Carlota | AE38: South | AF38: Chin | AG38: FM | AH38: 62 | AI38: 414 | AJ38: 574
A39: 40546 | B39: Sunshine | C39: East | D39: Pham | E39: FM | F39: 38 | G39: 722 | H39: 304 | AC39: 40546 | AD39: Carlota | AE39: South | AF39: Pham | AG39: FM | AH39: 38 | AI39: 418 | AJ39: 304
A40: 40569 | B40: Bellen | C40: West | D40: Pham | E40: FRED | F40: 61 | G40: 5000 | H40: 610 | AC40: 40569 | AD40: Carlota | AE40: South | AF40: Pham | AG40: FRED | AH40: 61 | AI40: 432 | AJ40: 610
...

Sheet Q7
A1: Filter the data set to show records that or for the West or MidWest Region and For Product Carlota
A3: Date | B3: Product | C3: Region | D3: SalesRep | E3: Customer | F3: Units | G3: Sales | H3: COGS
A4: 40563 | B4: Sunshine | C4: West | D4: Sioux | E4: YTR | F4: 58 | G4: 1102 | H4: 464
A5: 40573 | B5: Sunshine | C5: West | D5: Gault | E5: DFR | F5: 49 | G5: 931 | H5: 392
A6: 40548 | B6: Sunshine | C6: West | D6: Franks | E6: ET | F6: 12 | G6: 228 | H6: 96
A7: 40561 | B7: Sunshine | C7: West | D7: Sioux | E7: AST | F7: 8 | G7: 152 | H7: 64
A8: 40571 | B8: Sunset | C8: West | D8: Chin | E8: FM | F8: 62 | G8: 1302 | H8: 573.5
A9: 40550 | B9: Sunset | C9: West | D9: Pham | E9: T | F9: 61 | G9: 1281 | H9: 564.25
A10: 40550 | B10: Sunset | C10: West | D10: Pham | E10: WT | F10: 53 | G10: 1113 | H10: 490.25
A11: 40553 | B11: Quad | C11: West | D11: Smith | E11: KBTB | F11: 65 | G11: 1755 | H11: 942.5
A12: 40549 | B12: Quad | C12: West | D12: Sioux | E12: PCC | F12: 64 | G12: 1728 | H12: 928
A13: 40567 | B13: Quad | C13: West | D13: Gault | E13: HII | F13: 63 | G13: 1701 | H13: 913.5
A14: 40564 | B14: Quad | C14: West | D14: Gault | E14: ITW | F14: 56 | G14: 1512 | H14: 812
A15: 40545 | B15: Quad | C15: West | D15: Pham | E15: AST | F15: 30 | G15: 810 | H15: 435
... A108: 40566 | B108: Bellen | C108: East | D108: Gault | E108: DFGH | F108: 9 | G108: 198 | H108: 90

Sheet Q8
A1: Create A PivotTable that sums sales for each Month.
A3: Date | B3: SalesRep | C3: Sales | D3: Month
A4: 40255 | B4: Fred | C4: 73 | D4: =TEXT(A4,"mmmm yyyy") -> March 2010
A5: 40256 | B5: Jo | C5: 121 | D5: =TEXT(A5,"mmmm yyyy") -> March 2010
A6: 40257 | B6: Fred | C6: 167 | D6: =TEXT(A6,"mmmm yyyy") -> March 2010 | G6: Month | H6: Sum of Sales
A7: 40258 | B7: Joe | C7: 167 | D7: =TEXT(A7,"mmmm yyyy") -> March 2010 | G7: April 2010 | H7: 3003
A8: 40259 | B8: Sue | C8: 75 | D8: =TEXT(A8,"mmmm yyyy") -> March 2010 | G8: August 2010 | H8: 3468
A9: 40260 | B9: Fred | C9: 157 | D9: =TEXT(A9,"mmmm yyyy") -> March 2010 | G9: July 2010 | H9: 3515
A10: 40261 | B10: Sue | C10: 61 | D10: =TEXT(A10,"mmmm yyyy") -> March 2010 | G10: June 2010 | H10: 3664
A11: 40262 | B11: Fred | C11: 108 | D11: =TEXT(A11,"mmmm yyyy") -> March 2010 | G11: March 2010 | H11: 1522
A12: 40263 | B12: Jo | C12: 139 | D12: =TEXT(A12,"mmmm yyyy") -> March 2010 | G12: May 2010 | H12: 3365
A13: 40264 | B13: Sioux | C13: 130 | D13: =TEXT(A13,"mmmm yyyy") -> March 2010 | G13: October 2010 | H13: 968
A14: 40265 | B14: Sue | C14: 66 | D14: =TEXT(A14,"mmmm yyyy") -> March 2010 | G14: September 2010 | H14: 3240
A15: 40266 | B15: Sioux | C15: 86 | D15: =TEXT(A15,"mmmm yyyy") -> March 2010 | G15: Grand Total | H15: 22745
A16: 40267 | B16: Joe | C16: 122 | D16: =TEXT(A16,"mmmm yyyy") -> March 2010
A17: 40268 | B17: Sioux | C17: 50 | D17: =TEXT(A17,"mmmm yyyy") -> March 2010
A18: 40269 | B18: Sue | C18: 77 | D18: =TEXT(A18,"mmmm yyyy") -> April 2010
A19: 40270 | B19: Fred | C19: 140 | D19: =TEXT(A19,"mmmm yyyy") -> April 2010
A20: 40271 | B20: Sue | C20: 107 | D20: =TEXT(A20,"mmmm yyyy") -> April 2010
A21: 40272 | B21: Sioux | C21: 109 | D21: =TEXT(A21,"mmmm yyyy") -> April 2010
A22: 40273 | B22: Joe | C22: 121 | D22: =TEXT(A22,"mmmm yyyy") -> April 2010
A23: 40274 | B23: Fred | C23: 78 | D23: =TEXT(A23,"mmmm yyyy") -> April 2010
A24: 40275 | B24: Sioux | C24: 168 | D24: =TEXT(A24,"mmmm yyyy") -> April 2010
A25: 40276 | B25: Jo | C25: 88 | D25: =TEXT(A25,"mmmm yyyy") -> April 2010
A26: 40277 | B26: Chin | C26: 110 | D26: =TEXT(A26,"mmmm yyyy") -> April 2010
A27: 40278 | B27: Chin | C27: 132 | D27: =TEXT(A27,"mmmm yyyy") -> April 2010
... A208: 40459 | B208: Sue | C208: 146 | D208: =TEXT(A208,"mmmm yyyy") -> October 2010

Sheet Q9
A1: S.No | B1: Name | C1: fill short cuts | D1: marks 20M
A2: 1 | B2: Insert column | C2: ctrl+sift++
A3: 2 | B3: Delete Column | C3: ctrl+-
A4: 3 | B4: Print | C4: ctrl+p
A5: 4 | B5: Redo | C5: ctrl+y
A6: 5 | B6: bold font | C6: ctrl+b
A7: 6 | B7: Find | C7: ctrl+f
A8: 7 | B8: Open File | C8: ctrl+o
A9: 8 | B9: Freeze panes | C9: alt+w+F+f
A10: 9 | B10: Replace | C10: ctrl+h
A11: 10 | B11: Change Number to date | C11: ctrl+shift+#
A12: 11 | B12: Change date to Number | C12: ctrl+shift+~
A13: 12 | B13: select entire column | C13: ctrl+space
... A21: 20 | B21: Selet entire row | C21: ctrl+shift

Sheet Q10
A1: Q2. Use excel functions with the below conditions and derive the Person Status
K2: IF(A2>=90,"A",IF(A2>=75,"B",IF(A2>=60,"C",IF(A2>=40,"D","Fail"))))
C3: Condition
C4: >=60 | D4: Old
C5: >=30 & <=59 | D5: Middle
C6: >=18 & <=29 | D6: Young
C7: <18 | D7: Child
B9: SL.No | C9: Age | D9: Name | E9: Person Status
B10: 1 | C10: 65 | D10: RASIKLAL JETHALAL CHHAPAN | E10: =IF(C10>=60,"old",IF(AND(C10>=30,C10<=59),"middle",IF(AND(C10>=18,C10<=29),"young",IF(C10<18,"child")))) -> old
B11: 2 | C11: 67 | D11: SAROJ RASIKLAL CHHAPAN | E11: =IF(C11>=60,"old",IF(AND(C11>=30,C11<=59),"middle",IF(AND(C11>=18,C11<=29),"young",IF(C11<18,"child")))) -> old
B12: 3 | C12: 25 | D12: MAULIK VINODCHANDRA JADAWALA | E12: =IF(C12>=60,"old",IF(AND(C12>=30,C12<=59),"middle",IF(AND(C12>=18,C12<=29),"young",IF(C12<18,"child")))) -> young
B13: 4 | C13: 45 | D13: JIGAR BHUPESH CHHAPAN | E13: =IF(C13>=60,"old",IF(AND(C13>=30,C13<=59),"middle",IF(AND(C13>=18,C13<=29),"young",IF(C13<18,"child")))) -> middle
B14: 5 | C14: 15 | D14: HIMANSHU JOSHI | E14: =IF(C14>=60,"old",IF(AND(C14>=30,C14<=59),"middle",IF(AND(C14>=18,C14<=29),"young",IF(C14<18,"child")))) -> child
B15: 6 | C15: 80 | D15: GEETA VASHISHTHA DESAI | E15: =IF(C15>=60,"old",IF(AND(C15>=30,C15<=59),"middle",IF(AND(C15>=18,C15<=29),"young",IF(C15<18,"child")))) -> old
B16: 7 | C16: 40 | D16: HITENDRA RAJNIKANT DAVE | E16: =IF(C16>=60,"old",IF(AND(C16>=30,C16<=59),"middle",IF(AND(C16>=18,C16<=29),"young",IF(C16<18,"child")))) -> middle
B17: 8 | C17: 17 | D17: ARUNA V GARG | E17: =IF(C17>=60,"old",IF(AND(C17>=30,C17<=59),"middle",IF(AND(C17>=18,C17<=29),"young",IF(C17<18,"child")))) -> child
B18: 9 | C18: 95 | D18: DHAVAL NATVARLAL SHAH | E18: =IF(C18>=60,"old",IF(AND(C18>=30,C18<=59),"middle",IF(AND(C18>=18,C18<=29),"young",IF(C18<18,"child")))) -> old
B19: 10 | C19: 22 | D19: NATVARLAL HIRALAL SHAH | E19: =IF(C19>=60,"old",IF(AND(C19>=30,C19<=59),"middle",IF(AND(C19>=18,C19<=29),"young",IF(C19<18,"child")))) -> young

Sheet Q11
A1: :
B4: Raw Data | F4: Area | G4: Total Amount | H4: Total Count
B5: Area | C5: Sub Area | D5: grossamt | F5: No Area Given | G5: =SUMIF(B5:B303,F5,D5:D303) -> 50000 | H5: =COUNTIF(B6:B303,F5) -> 1
B6: Hardware | C6: Damaged-Malfunctioned | D6: 50000 | F6: AirWatch | G6: =SUMIF(B6:B304,F6,D6:D304) -> 500000 | H6: =COUNTIF(B7:B304,F6) -> 1
B7: Hardware | C7: Complete System | D7: 195000 | F7: Client Specific | G7: =SUMIF(B7:B305,F7,D7:D305) -> 9964844 | H7: =COUNTIF(B8:B305,F7) -> 18
B8: Hardware | C8: Usage | D8: 50000 | F8: Connectivity | G8: =SUMIF(B8:B306,F8,D8:D306) -> 9825000 | H8: =COUNTIF(B9:B306,F8) -> 13
B9: Off the Shelf | C9: Windows 7 | D9: 1000000 | F9: Email | G9: =SUMIF(B9:B307,F9,D9:D307) -> 1300000 | H9: =COUNTIF(B10:B307,F9) -> 3
B10: No Area Given | C10: No Sub Area Given | D10: 50000 | F10: Field Planning | G10: =SUMIF(B10:B308,F10,D10:D308) -> 440000 | H10: =COUNTIF(B11:B308,F10) -> 4
B11: iPad - Hardware | C11: Lost/Stolen | D11: 100100 | F11: Hardware | G11: =SUMIF(B11:B309,F11,D11:D309) -> 25274300 | H11: =COUNTIF(B12:B309,F11) -> 38
B12: Veeva | C12: Calls | D12: 50000 | F12: Hardware - iPad | G12: =SUMIF(B12:B310,F12,D12:D310) -> 1220000 | H12: =COUNTIF(B13:B310,F12) -> 3
B13: iPad - Hardware | C13: Request | D13: 450000 | F13: iPad | G13: =SUMIF(B13:B311,F13,D13:D311) -> 20191282 | H13: =COUNTIF(B14:B311,F13) -> 15
B14: Veeva | C14: Calls | D14: 20000000 | F14: iPad - Connectivity | G14: =SUMIF(B14:B312,F14,D14:D312) -> 6000 | H14: =COUNTIF(B15:B312,F14) -> 1
B15: Veeva | C15: Calls | D15: 10300 | F15: iPad - Hardware | G15: =SUMIF(B15:B313,F15,D15:D313) -> 65000 | H15: =COUNTIF(B16:B313,F15) -> 4
B16: Veeva | C16: Accounts | D16: 225000 | F16: iPad - Software | G16: =SUMIF(B16:B314,F16,D16:D314) -> 350000 | H16: =COUNTIF(B17:B314,F16) -> 2
B17: iPad - Hardware | C17: Damaged/Malfunctioned | D17: 25000 | F17: iPhone | G17: =SUMIF(B17:B315,F17,D17:D315) -> 2050000 | H17: =COUNTIF(B18:B315,F17) -> 7
... B22: iPad - Hardware | C22: Damaged/Malfunctioned | D22: 25000 | F22: Vmobile | G22: =SUMIF(B22:B320,F22,D22:D320) -> 6412789 | H22: =COUNTIF(B23:B320,F22) -> 16
B23: iPad - Software | C23: Application | D23: 50000 | F23: Total | G23: =SUM(G5:G22) -> 175703471 | H23: =SUM(H5:H22) -> 286
B24: iPad - Hardware | C24: Lost/Stolen | D24: 5000
B25: iPad - Connectivity | C25: Wireless | D25: 6000
